<?xml version="1.0" ?>
<sdf version="1.8">
  <world name="minzanix_world">
    <!-- Physics -->
    <physics name="1ms" type="ignored">
      <max_step_size>0.001</max_step_size>
      <real_time_factor>1.0</real_time_factor>
    </physics>

    <!-- Plugins -->
    <plugin
      filename="gz-sim-physics-system"
      name="gz::sim::systems::Physics">
    </plugin>
    <plugin
      filename="gz-sim-user-commands-system"
      name="gz::sim::systems::UserCommands">
    </plugin>
    <plugin
      filename="gz-sim-scene-broadcaster-system"
      name="gz::sim::systems::SceneBroadcaster">
    </plugin>
    <plugin
      filename="gz-sim-sensors-system"
      name="gz::sim::systems::Sensors">
      <render_engine>ogre2</render_engine>
    </plugin>

    <!-- Lighting -->
    <light type="directional" name="sun">
      <cast_shadows>true</cast_shadows>
      <pose>0 0 10 0 0 0</pose>
      <diffuse>0.8 0.8 0.8 1</diffuse>
      <specular>0.2 0.2 0.2 1</specular>
      <attenuation>
        <range>1000</range>
        <constant>0.9</constant>
        <linear>0.01</linear>
        <quadratic>0.001</quadratic>
      </attenuation>
      <direction>-0.5 0.1 -0.9</direction>
    </light>

    <!-- Ground Plane -->
    <model name="ground_plane">
      <static>true</static>
      <link name="link">
        <collision name="collision">
          <geometry>
            <plane>
              <normal>0 0 1</normal>
            </plane>
          </geometry>
        </collision>
        <visual name="visual">
          <geometry>
            <plane>
              <normal>0 0 1</normal>
              <size>100 100</size>
            </plane>
          </geometry>
          <material>
            <ambient>0.8 0.8 0.8 1</ambient>
            <diffuse>0.8 0.8 0.8 1</diffuse>
            <specular>0.8 0.8 0.8 1</specular>
          </material>
        </visual>
      </link>
    </model>

    <!-- X500 Quadcopter -->
    <model name="x500">
      <pose>0 0 0.5 0 0 0</pose>
      
      <!-- Base link (body) -->
      <link name="base_link">
        <inertial>
          <pose>0 0 0 0 0 0</pose>
          <mass>1.5</mass>
          <inertia>
            <ixx>0.029125</ixx>
            <ixy>0</ixy>
            <ixz>0</ixz>
            <iyy>0.029125</iyy>
            <iyz>0</iyz>
            <izz>0.055225</izz>
          </inertia>
        </inertial>

        <visual name="visual">
          <geometry>
            <box>
              <size>0.47 0.47 0.11</size>
            </box>
          </geometry>
          <material>
            <ambient>0.2 0.2 0.2 1</ambient>
            <diffuse>0.3 0.3 0.3 1</diffuse>
          </material>
        </visual>

        <collision name="collision">
          <geometry>
            <box>
              <size>0.47 0.47 0.11</size>
            </box>
          </geometry>
        </collision>

        <!-- IMU Sensor -->
        <sensor name="imu_sensor" type="imu">
          <always_on>1</always_on>
          <update_rate>250</update_rate>
          <visualize>true</visualize>
          <topic>/imu</topic>
          <enable_metrics>false</enable_metrics>
          <imu>
            <angular_velocity>
              <x>
                <noise type="gaussian">
                  <mean>0.0</mean>
                  <stddev>0.009</stddev>
                </noise>
              </x>
              <y>
                <noise type="gaussian">
                  <mean>0.0</mean>
                  <stddev>0.009</stddev>
                </noise>
              </y>
              <z>
                <noise type="gaussian">
                  <mean>0.0</mean>
                  <stddev>0.009</stddev>
                </noise>
              </z>
            </angular_velocity>
            <linear_acceleration>
              <x>
                <noise type="gaussian">
                  <mean>0.0</mean>
                  <stddev>0.017</stddev>
                </noise>
              </x>
              <y>
                <noise type="gaussian">
                  <mean>0.0</mean>
                  <stddev>0.017</stddev>
                </noise>
              </y>
              <z>
                <noise type="gaussian">
                  <mean>0.0</mean>
                  <stddev>0.017</stddev>
                </noise>
              </z>
            </linear_acceleration>
          </imu>
        </sensor>

        <!-- Barometer Sensor -->
        <sensor name="air_pressure_sensor" type="air_pressure">
          <always_on>1</always_on>
          <update_rate>50</update_rate>
          <visualize>false</visualize>
          <topic>/air_pressure</topic>
          <air_pressure>
            <pressure>
              <noise type="gaussian">
                <mean>0.0</mean>
                <stddev>1.0</stddev>
              </noise>
            </pressure>
          </air_pressure>
        </sensor>
      </link>

      <!-- Rotor 0 (Front Right) -->
      <link name="rotor_0">
        <pose>0.13 -0.22 0.023 0 0 0</pose>
        <inertial>
          <mass>0.005</mass>
          <inertia>
            <ixx>9.75e-07</ixx>
            <iyy>0.000166704</iyy>
            <izz>0.000167604</izz>
          </inertia>
        </inertial>
        <visual name="visual">
          <geometry>
            <cylinder>
              <radius>0.128</radius>
              <length>0.005</length>
            </cylinder>
          </geometry>
          <material>
            <ambient>1 0 0 1</ambient>
            <diffuse>1 0 0 1</diffuse>
          </material>
        </visual>
      </link>

      <joint name="rotor_0_joint" type="revolute">
        <parent>base_link</parent>
        <child>rotor_0</child>
        <axis>
          <xyz>0 0 1</xyz>
          <limit>
            <lower>-1e+12</lower>
            <upper>1e+12</upper>
            <effort>-1</effort>
            <velocity>-1</velocity>
          </limit>
        </axis>
      </joint>

      <!-- Rotor 1 (Rear Left) -->
      <link name="rotor_1">
        <pose>-0.13 0.20 0.023 0 0 0</pose>
        <inertial>
          <mass>0.005</mass>
          <inertia>
            <ixx>9.75e-07</ixx>
            <iyy>0.000166704</iyy>
            <izz>0.000167604</izz>
          </inertia>
        </inertial>
        <visual name="visual">
          <geometry>
            <cylinder>
              <radius>0.128</radius>
              <length>0.005</length>
            </cylinder>
          </geometry>
          <material>
            <ambient>0 1 0 1</ambient>
            <diffuse>0 1 0 1</diffuse>
          </material>
        </visual>
      </link>

      <joint name="rotor_1_joint" type="revolute">
        <parent>base_link</parent>
        <child>rotor_1</child>
        <axis>
          <xyz>0 0 1</xyz>
          <limit>
            <lower>-1e+12</lower>
            <upper>1e+12</upper>
            <effort>-1</effort>
            <velocity>-1</velocity>
          </limit>
        </axis>
      </joint>

      <!-- Rotor 2 (Front Left) -->
      <link name="rotor_2">
        <pose>0.13 0.22 0.023 0 0 0</pose>
        <inertial>
          <mass>0.005</mass>
          <inertia>
            <ixx>9.75e-07</ixx>
            <iyy>0.000166704</iyy>
            <izz>0.000167604</izz>
          </inertia>
        </inertial>
        <visual name="visual">
          <geometry>
            <cylinder>
              <radius>0.128</radius>
              <length>0.005</length>
            </cylinder>
          </geometry>
          <material>
            <ambient>0 0 1 1</ambient>
            <diffuse>0 0 1 1</diffuse>
          </material>
        </visual>
      </link>

      <joint name="rotor_2_joint" type="revolute">
        <parent>base_link</parent>
        <child>rotor_2</child>
        <axis>
          <xyz>0 0 1</xyz>
          <limit>
            <lower>-1e+12</lower>
            <upper>1e+12</upper>
            <effort>-1</effort>
            <velocity>-1</velocity>
          </limit>
        </axis>
      </joint>

      <!-- Rotor 3 (Rear Right) -->
      <link name="rotor_3">
        <pose>-0.13 -0.20 0.023 0 0 0</pose>
        <inertial>
          <mass>0.005</mass>
          <inertia>
            <ixx>9.75e-07</ixx>
            <iyy>0.000166704</iyy>
            <izz>0.000167604</izz>
          </inertia>
        </inertial>
        <visual name="visual">
          <geometry>
            <cylinder>
              <radius>0.128</radius>
              <length>0.005</length>
            </cylinder>
          </geometry>
          <material>
            <ambient>1 1 0 1</ambient>
            <diffuse>1 1 0 1</diffuse>
          </material>
        </visual>
      </link>

      <joint name="rotor_3_joint" type="revolute">
        <parent>base_link</parent>
        <child>rotor_3</child>
        <axis>
          <xyz>0 0 1</xyz>
          <limit>
            <lower>-1e+12</lower>
            <upper>1e+12</upper>
            <effort>-1</effort>
            <velocity>-1</velocity>
          </limit>
        </axis>
      </joint>

      <!-- Motor Model Plugins -->
      <plugin filename="gz-sim-multicopter-motor-model-system"
        name="gz::sim::systems::MulticopterMotorModel">
        <jointName>rotor_0_joint</jointName>
        <linkName>rotor_0</linkName>
        <turningDirection>cw</turningDirection>
        <timeConstantUp>0.0125</timeConstantUp>
        <timeConstantDown>0.025</timeConstantDown>
        <maxRotVelocity>1100.0</maxRotVelocity>
        <motorConstant>8.54858e-06</motorConstant>
        <momentConstant>0.016</momentConstant>
        <commandSubTopic>command/motor_speed</commandSubTopic>
        <motorNumber>0</motorNumber>
        <rotorDragCoefficient>8.06428e-05</rotorDragCoefficient>
        <rollingMomentCoefficient>1e-06</rollingMomentCoefficient>
        <rotorVelocitySlowdownSim>10</rotorVelocitySlowdownSim>
        <motorType>velocity</motorType>
      </plugin>

      <plugin filename="gz-sim-multicopter-motor-model-system"
        name="gz::sim::systems::MulticopterMotorModel">
        <jointName>rotor_1_joint</jointName>
        <linkName>rotor_1</linkName>
        <turningDirection>cw</turningDirection>
        <timeConstantUp>0.0125</timeConstantUp>
        <timeConstantDown>0.025</timeConstantDown>
        <maxRotVelocity>1100.0</maxRotVelocity>
        <motorConstant>8.54858e-06</motorConstant>
        <momentConstant>0.016</momentConstant>
        <commandSubTopic>command/motor_speed</commandSubTopic>
        <motorNumber>1</motorNumber>
        <rotorDragCoefficient>8.06428e-05</rotorDragCoefficient>
        <rollingMomentCoefficient>1e-06</rollingMomentCoefficient>
        <rotorVelocitySlowdownSim>10</rotorVelocitySlowdownSim>
        <motorType>velocity</motorType>
      </plugin>

      <plugin filename="gz-sim-multicopter-motor-model-system"
        name="gz::sim::systems::MulticopterMotorModel">
        <jointName>rotor_2_joint</jointName>
        <linkName>rotor_2</linkName>
        <turningDirection>ccw</turningDirection>
        <timeConstantUp>0.0125</timeConstantUp>
        <timeConstantDown>0.025</timeConstantDown>
        <maxRotVelocity>1100.0</maxRotVelocity>
        <motorConstant>8.54858e-06</motorConstant>
        <momentConstant>0.016</momentConstant>
        <commandSubTopic>command/motor_speed</commandSubTopic>
        <motorNumber>2</motorNumber>
        <rotorDragCoefficient>8.06428e-05</rotorDragCoefficient>
        <rollingMomentCoefficient>1e-06</rollingMomentCoefficient>
        <rotorVelocitySlowdownSim>10</rotorVelocitySlowdownSim>
        <motorType>velocity</motorType>
      </plugin>

      <plugin filename="gz-sim-multicopter-motor-model-system"
        name="gz::sim::systems::MulticopterMotorModel">
        <jointName>rotor_3_joint</jointName>
        <linkName>rotor_3</linkName>
        <turningDirection>ccw</turningDirection>
        <timeConstantUp>0.0125</timeConstantUp>
        <timeConstantDown>0.025</timeConstantDown>
        <maxRotVelocity>1100.0</maxRotVelocity>
        <motorConstant>8.54858e-06</motorConstant>
        <momentConstant>0.016</momentConstant>
        <commandSubTopic>command/motor_speed</commandSubTopic>
        <motorNumber>3</motorNumber>
        <rotorDragCoefficient>8.06428e-05</rotorDragCoefficient>
        <rollingMomentCoefficient>1e-06</rollingMomentCoefficient>
        <rotorVelocitySlowdownSim>10</rotorVelocitySlowdownSim>
        <motorType>velocity</motorType>
      </plugin>
    </model>

  </world>
</sdf>
